#VRML_SIM R2023a utf8
PROTO FourWheelsRobot [
  field SFVec3f    translation  0 0 0
  field SFRotation rotation     0 0 1 0
  field SFFloat    bodyMass     1
]
{
  Robot {
  translation 0.132682 0.0127707 0.023095
  rotation -0.053262993298362246 0.03024450109940963 0.9981223991566096 0.714564716837426
  scale 0.563741 0.563741 0.563741
  children [
    DEF body Shape {
      appearance PBRAppearance {
        baseColor 1 0 0
        baseColorMap ImageTexture {
        }
        metalness 0
      }
      geometry Box {
        size 0.2 0.1 0.05
      }
    }
    HingeJoint {
      jointParameters HingeJointParameters {
        position 31.26309824419052
        anchor 0.05 0.06 0
      }
      device [
        RotationalMotor {
          name "wheel1"
        }
      ]
      endPoint Solid {
        translation 0.05000000091689207 0.059999296078720475 -9.171972939065532e-07
        rotation -1 1.184446096441787e-10 -6.553569611725281e-11 2.20631087521448
        children [
          DEF Wheel Shape {
            appearance PBRAppearance {
              baseColor 0 1 0
              metalness 0
            }
            geometry Cylinder {
              height 0.02
              radius 0.04
            }
          }
        ]
        boundingObject USE Wheel
        physics DEF physics_wh Physics {
        }
      }
    }
    HingeJoint {
      jointParameters HingeJointParameters {
        position 31.26309879889012
        anchor -0.05 0.06 0
      }
      device [
        RotationalMotor {
          name "wheel2"
        }
      ]
      endPoint Solid {
        translation -0.05 0.06 0
        rotation -1 0 0 4.8651130441873995
        children [
          DEF Wheel Shape {
            appearance PBRAppearance {
              baseColor 0 1 0
              metalness 0
            }
            geometry Cylinder {
              height 0.02
              radius 0.04
            }
          }
        ]
        name "solid(3)"
        boundingObject USE Wheel
        physics DEF physics_wh Physics {
        }
      }
    }
    HingeJoint {
      jointParameters HingeJointParameters {
        position 31.26309867384686
        anchor 0.05 -0.06 0
      }
      device [
        RotationalMotor {
          name "wheel3"
        }
      ]
      endPoint Solid {
        translation 0.05 -0.06 0
        rotation -0.9999999999999999 0 0 4.86521316923066
        children [
          USE Wheel
        ]
        name "solid(1)"
        boundingObject USE Wheel
        physics USE physics_wh
      }
    }
    HingeJoint {
      jointParameters HingeJointParameters {
        position 31.263099448705596
        anchor -0.05 -0.06 0
      }
      device [
        RotationalMotor {
          name "wheel4"
        }
      ]
      endPoint Solid {
        translation -0.05 -0.06 0
        rotation -1 0 0 4.865212394371923
        children [
          USE Wheel
        ]
        name "solid(2)"
        boundingObject USE Wheel
        physics USE physics_wh
      }
    }
    DistanceSensor {
      translation 0.1 0.02 0
      rotation 0 0 1 0.87
      children [
        DEF sensor Shape {
          appearance PBRAppearance {
            baseColor 0 1 1
            metalness 0
          }
          geometry Box {
            size 0.01 0.01 0.01
          }
        }
      ]
      name "ds_left"
      boundingObject USE sensor
      physics Physics {
      }
    }
    DistanceSensor {
      translation 0.1 -0.02 0
      rotation 0 0 -1 0.87
      children [
        DEF sensor Shape {
          appearance PBRAppearance {
            baseColor 0 1 1
            metalness 0
          }
          geometry Box {
            size 0.01 0.01 0.01
          }
        }
      ]
      name "ds_right"
      boundingObject USE sensor
      physics Physics {
      }
    }
  ]
  boundingObject USE body
  physics Physics {
  }
  controller "obstacle_avoid"
}
}