#VRML_SIM R2023a utf8

EXTERNPROTO "https://raw.githubusercontent.com/cyberbotics/webots/R2023a/projects/objects/backgrounds/protos/TexturedBackground.proto"
EXTERNPROTO "https://raw.githubusercontent.com/cyberbotics/webots/R2023a/projects/objects/backgrounds/protos/TexturedBackgroundLight.proto"
EXTERNPROTO "https://raw.githubusercontent.com/cyberbotics/webots/R2023a/projects/objects/floors/protos/Floor.proto"

WorldInfo {
}
Viewpoint {
  orientation 0.16399569405893724 -0.020389041124837498 -0.9862503228552766 3.3855918165680334
  position 0.937834356713376 -0.03796752320998367 0.4595568523380649
}
TexturedBackground {
}
TexturedBackgroundLight {
}
Floor {
  size 1 1
}
Robot {
  translation -0.0166521 0.01005 0.0299546
  rotation -1.3425451680392069e-24 -1.0906287763794104e-24 1 1.0471999999999997
  scale 0.563741 0.563741 0.563741
  children [
    DEF body Shape {
      appearance PBRAppearance {
        baseColor 1 0 0
        baseColorMap ImageTexture {
        }
        metalness 0
      }
      geometry Box {
        size 0.2 0.1 0.05
      }
    }
    HingeJoint {
      jointParameters HingeJointParameters {
        anchor 0.05 0.06 0
      }
      device [
        RotationalMotor {
          name "wheel1"
        }
      ]
      endPoint Solid {
        translation 0.05 0.06 0
        rotation 1 0 0 1.5709
        children [
          DEF Wheel Shape {
            appearance PBRAppearance {
              baseColor 0 1 0
              metalness 0
            }
            geometry Cylinder {
              height 0.02
              radius 0.04
            }
          }
        ]
        boundingObject USE Wheel
        physics DEF physics_wh Physics {
        }
      }
    }
    HingeJoint {
      jointParameters HingeJointParameters {
        anchor -0.05 0.06 0
      }
      device [
        RotationalMotor {
          name "wheel2"
        }
      ]
      endPoint Solid {
        translation -0.05 0.06 0
        rotation 1 0 0 1.5709
        children [
          DEF Wheel Shape {
            appearance PBRAppearance {
              baseColor 0 1 0
              metalness 0
            }
            geometry Cylinder {
              height 0.02
              radius 0.04
            }
          }
        ]
        name "solid(3)"
        boundingObject USE Wheel
        physics DEF physics_wh Physics {
        }
      }
    }
    HingeJoint {
      jointParameters HingeJointParameters {
        anchor 0.05 -0.06 0
      }
      device [
        RotationalMotor {
          name "wheel3"
        }
      ]
      endPoint Solid {
        translation 0.05 -0.06 0
        rotation 1 0 0 1.5708
        children [
          USE Wheel
        ]
        name "solid(1)"
        boundingObject USE Wheel
        physics USE physics_wh
      }
    }
    HingeJoint {
      jointParameters HingeJointParameters {
        anchor -0.05 -0.06 0
      }
      device [
        RotationalMotor {
          name "wheel4"
        }
      ]
      endPoint Solid {
        translation -0.05 -0.06 0
        rotation 1 0 0 1.5708
        children [
          USE Wheel
        ]
        name "solid(2)"
        boundingObject USE Wheel
        physics USE physics_wh
      }
    }
    DistanceSensor {
      translation 0.1 0.02 0
      rotation 0 0 1 0.87
      children [
        DEF sensor Shape {
          appearance PBRAppearance {
            baseColor 0 1 1
            metalness 0
          }
          geometry Box {
            size 0.01 0.01 0.01
          }
        }
      ]
      name "ds_left"
      boundingObject USE sensor
      physics Physics {
      }
    }
    DistanceSensor {
      translation 0.1 -0.02 0
      rotation 0 0 -1 0.87
      children [
        DEF sensor Shape {
          appearance PBRAppearance {
            baseColor 0 1 1
            metalness 0
          }
          geometry Box {
            size 0.01 0.01 0.01
          }
        }
      ]
      name "ds_right"
      boundingObject USE sensor
      physics Physics {
      }
    }
  ]
  boundingObject USE body
  physics Physics {
  }
  controller "obstacle_avoid"
}
